Workbook

Sheet סיכום
A1: 5 מאפים בעלות נמוכה – סיכום עלויות (רמי לוי)
A3: מתכון | B3: עלות מתכון | C3: יחידות | D3: עלות ליחידה
A4: 1. מאפינס בטטה ותירס (גם לתינוקת) | B4: =מתכונים!G12 -> 17.675797 | C4: 12 | D4: =B4/C4 -> 1.4729831
A5: 2. מאפינס ברוקולי וקישוא (גם לתינוקת) | B5: =מתכונים!G22 -> 17.480917 | C5: 12 | D5: =B5/C5 -> 1.4567431
A6: 3. פיצה מגש לריבועים | B6: =מתכונים!G33 -> 27.440297 | C6: 12 | D6: =B6/C6 -> 2.2866914
A7: 4. שבלולי ברוקולי וקוטג' | B7: =מתכונים!G43 -> 26.990833 | C7: 12 | D7: =B7/C7 -> 2.2492361
A8: 5. סמבוסקי פיצה וטונה (מהסרטון) | B8: =מתכונים!G55 -> 18.165 | C8: 20 | D8: =B8/C8 -> 0.90825
A9: סה"כ 5 מתכונים (עלות שימוש בפועל) | B9: =SUM(B4:B8) -> 107.75284 | C9: =SUM(C4:C8) -> 68 | D9: =B9/C9 -> 1.5846007
A12: רשימת קניות – סל אחד ברמי לוי
A13: מוצר | B13: כמות נדרשת | C13: אריזות לקנייה | D13: עלות בקופה | E13: יחידה
A14: =מחירים!A5 -> קמח כוסמין מלא 100% נפלאות 1 ק"ג | B14: =SUMIF(מתכונים!$B:$B,A14,מתכונים!$C:$C) -> 1100 | C14: =IF(מחירים!F5="כן",B14/מחירים!C5,ROUNDUP(B14/מחירים!C5,0)) -> 2 | D14: =C14*מחירים!D5 -> 29.4 | E14: =מחירים!B5 -> גרם
A15: =מחירים!A6 -> יוגורט 3% גביע 200 גרם | B15: =SUMIF(מתכונים!$B:$B,A15,מתכונים!$C:$C) -> 1200 | C15: =IF(מחירים!F6="כן",B15/מחירים!C6,ROUNDUP(B15/מחירים!C6,0)) -> 6 | D15: =C15*מחירים!D6 -> 23.4 | E15: =מחירים!B6 -> גרם
A16: =מחירים!A7 -> ביצים L, 12 יח' | B16: =SUMIF(מתכונים!$B:$B,A16,מתכונים!$C:$C) -> 6 | C16: =IF(מחירים!F7="כן",B16/מחירים!C7,ROUNDUP(B16/מחירים!C7,0)) -> 1 | D16: =C16*מחירים!D7 -> 14 | E16: =מחירים!B7 -> יחידה
A17: =מחירים!A8 -> שמן קנולה רמי לוי 1 ליטר | B17: =SUMIF(מתכונים!$B:$B,A17,מתכונים!$C:$C) -> 210 | C17: =IF(מחירים!F8="כן",B17/מחירים!C8,ROUNDUP(B17/מחירים!C8,0)) -> 1 | D17: =C17*מחירים!D8 -> 8.9 | E17: =מחירים!B8 -> מ"ל
A18: =מחירים!A9 -> אבקת אפייה 150 גרם | B18: =SUMIF(מתכונים!$B:$B,A18,מתכונים!$C:$C) -> 44 | C18: =IF(מחירים!F9="כן",B18/מחירים!C9,ROUNDUP(B18/מחירים!C9,0)) -> 1 | D18: =C18*מחירים!D9 -> 4.9 | E18: =מחירים!B9 -> גרם
A19: =מחירים!A10 -> בטטה (לק"ג) | B19: =SUMIF(מתכונים!$B:$B,A19,מתכונים!$C:$C) -> 300 | C19: =IF(מחירים!F10="כן",B19/מחירים!C10,ROUNDUP(B19/מחירים!C10,0)) -> 0.3 | D19: =C19*מחירים!D10 -> 2.37 | E19: =מחירים!B10 -> גרם
A20: =מחירים!A11 -> קישוא (לק"ג) | B20: =SUMIF(מתכונים!$B:$B,A20,מתכונים!$C:$C) -> 350 | C20: =IF(מחירים!F11="כן",B20/מחירים!C11,ROUNDUP(B20/מחירים!C11,0)) -> 0.35 | D20: =C20*מחירים!D11 -> 3.115 | E20: =מחירים!B11 -> גרם
A21: =מחירים!A12 -> ברוקולי קפוא רמי לוי 800 גרם | B21: =SUMIF(מתכונים!$B:$B,A21,מתכונים!$C:$C) -> 550 | C21: =IF(מחירים!F12="כן",B21/מחירים!C12,ROUNDUP(B21/מחירים!C12,0)) -> 1 | D21: =C21*מחירים!D12 -> 13.9 | E21: =מחירים!B12 -> גרם
A22: =מחירים!A13 -> תירס מתוק שימורים רמי לוי 335 גרם | B22: =SUMIF(מתכונים!$B:$B,A22,מתכונים!$C:$C) -> 150 | C22: =IF(מחירים!F13="כן",B22/מחירים!C13,ROUNDUP(B22/מחירים!C13,0)) -> 1 | D22: =C22*מחירים!D13 -> 8.4 | E22: =מחירים!B13 -> גרם (מסונן)
A23: =מחירים!A14 -> קוטג' 5% 250 גרם | B23: =SUMIF(מתכונים!$B:$B,A23,מתכונים!$C:$C) -> 400 | C23: =IF(מחירים!F14="כן",B23/מחירים!C14,ROUNDUP(B23/מחירים!C14,0)) -> 2 | D23: =C23*מחירים!D14 -> 13.2 | E23: =מחירים!B14 -> גרם
A24: =מחירים!A15 -> מוצרלה מגורדת 200 גרם | B24: =SUMIF(מתכונים!$B:$B,A24,מתכונים!$C:$C) -> 150 | C24: =IF(מחירים!F15="כן",B24/מחירים!C15,ROUNDUP(B24/מחירים!C15,0)) -> 1 | D24: =C24*מחירים!D15 -> 19.7 | E24: =מחירים!B15 -> גרם
A25: =מחירים!A16 -> טונה בשמן סטארקיסט 4×160 גרם | B25: =SUMIF(מתכונים!$B:$B,A25,מתכונים!$C:$C) -> 1 | C25: =IF(מחירים!F16="כן",B25/מחירים!C16,ROUNDUP(B25/מחירים!C16,0)) -> 1 | D25: =C25*מחירים!D16 -> 19.7 | E25: =מחירים!B16 -> קופסה
... A29: =מחירים!A20 -> שומשום רמי לוי 400 גרם | B29: =SUMIF(מתכונים!$B:$B,A29,מתכונים!$C:$C) -> 10 | C29: =IF(מחירים!F20="כן",B29/מחירים!C20,ROUNDUP(B29/מחירים!C20,0)) -> 1 | D29: =C29*מחירים!D20 -> 17 | E29: =מחירים!B20 -> גרם
A30: סה"כ בקופה | D30: =SUM(D14:D29) -> 188.685
A31: מה נשאר בבית אחרי ההכנה (שווי) | D31: =D30-B9 -> 80.932156
A33: הערות:
A34: • 'עלות שימוש' = רק מה שנכנס למאפים. 'בקופה' = אריזות שלמות (נשאר קמח, ביצים, שמן, אבקת אפייה, טונה ותירס לפעם הבאה).
A35: • ויקטורי: בכל מוצר שנמצא בשתי הרשתות, רמי לוי היה זול או שווה (ביצים, קוטג', טונה). לכן הסל כולו ברמי לוי, עדיף באונליין.
A36: • מחירים צהובים בגיליון 'מחירים' הם הערכה. לעדכן אותם לפי האתר, וכל העלויות יתעדכנו אוטומטית.
A37: • מאפינס 1-2 לתינוקת: בלי מלח, תירס טחון, קוטג' בכמות קטנה בלבד.

Sheet מחירים
A1: מחירי מוצרים – רמי לוי מול ויקטורי (אזור חדרה / אונליין), נבדק 13.10.2026
A2: כחול = נתון שהוזן ידנית. ירוק = מחיר שאומת. צהוב = הערכה, יש לבדוק באתר לפני קנייה. מקור: chp.co.il (נתוני חוק שקיפות המחירים).
A4: מוצר | B4: יחידת מידה | C4: כמות באריזה | D4: מחיר רמי לוי | E4: מחיר ויקטורי | F4: נמכר לפי משקל? | G4: סטטוס | H4: הערות
A5: קמח כוסמין מלא 100% נפלאות 1 ק"ג | B5: גרם | C5: 1000 | D5: 14.7 | E5: לא נמצא | F5: לא | G5: מאומת | H5: רמי לוי אונליין 14.70; בסניף 14.90. ויקטורי – לא נמצא
A6: יוגורט 3% גביע 200 גרם | B6: גרם | C6: 200 | D6: 3.9 | E6: לא נמצא | F6: לא | G6: הערכה | H6: מחיר לא קריא במקור; מבצעים נראו ב-4.00. עדיף מותג פרטי / מארז
A7: ביצים L, 12 יח' | B7: יחידה | C7: 12 | D7: 14 | E7: 14.24 | F7: לא | G7: מאומת | H7: מחיר מפוקח
A8: שמן קנולה רמי לוי 1 ליטר | B8: מ"ל | C8: 1000 | D8: 8.9 | E8: לא נמצא | F8: לא | G8: מאומת | H8: מבצע בסניף: 7.50
A9: אבקת אפייה 150 גרם | B9: גרם | C9: 150 | D9: 4.9 | E9: לא נמצא | F9: לא | G9: הערכה | H9: מחיר לא קריא במקור
A10: בטטה (לק"ג) | B10: גרם | C10: 1000 | D10: 7.9 | E10: לא נמצא | F10: כן | G10: הערכה | H10: ירק במשקל – מחיר משתנה שבועית
A11: קישוא (לק"ג) | B11: גרם | C11: 1000 | D11: 8.9 | E11: לא נמצא | F11: כן | G11: הערכה | H11: ירק במשקל – מחיר משתנה שבועית
A12: ברוקולי קפוא רמי לוי 800 גרם | B12: גרם | C12: 800 | D12: 13.9 | E12: לא נמצא | F12: לא | G12: מאומת | H12: חסלט 600 גרם: 29.60 ברמי לוי / 31.90 בוויקטורי – המותג הפרטי זול פי 2.8
A13: תירס מתוק שימורים רמי לוי 335 גרם | B13: גרם (מסונן) | C13: 230 | D13: 8.4 | E13: לא נמצא | F13: לא | G13: מאומת | H13: אונליין 8.40; בסניף 7.90 ובמבצע 5.00. משקל מסונן כ-230 גרם
A14: קוטג' 5% 250 גרם | B14: גרם | C14: 250 | D14: 6.6 | E14: 6.9 | F14: לא | G14: מאומת | H14: ויקטורי אונליין 6.90; ויקטורי עמק חפר 7.10
A15: מוצרלה מגורדת 200 גרם | B15: גרם | C15: 200 | D15: 19.7 | E15: לא נמצא | F15: לא | G15: מאומת | H15: רמי לוי אונליין 19.70; בסניף 24.70 (מבצע 19.90)
A16: טונה בשמן סטארקיסט 4×160 גרם | B16: קופסה | C16: 4 | D16: 19.7 | E16: 23 | F16: לא | G16: מאומת | H16: רמי לוי אונליין 19.70; ויקטורי אונליין 25.90 (מבצע 23.00)
A17: רסק עגבניות 100 גרם | B17: גרם | C17: 100 | D17: 1.9 | E17: לא נמצא | F17: לא | G17: הערכה | H17: מחיר לא קריא במקור
A18: קמח לבן רמי לוי 1 ק"ג | B18: גרם | C18: 1000 | D18: 3.8 | E18: לא נמצא | F18: לא | G18: מאומת | H18: מותג פרטי, בסניף ובאונליין 3.80
A19: גבינה צהובה 28% מהדלפק (לק"ג) | B19: גרם | C19: 1000 | D19: 31 | E19: לא נמצא | F19: כן | G19: מאומת | H19: דלפק רמי לוי 31 ₪ לק"ג (מעריב, השוואת סל). לבקש פרוס דק או לגרד בבית
A20: שומשום רמי לוי 400 גרם | B20: גרם | C20: 400 | D20: 17 | E20: לא נמצא | F20: לא | G20: הערכה | H20: מחיר לא קריא במקור (כ-17-18). אפשר לוותר, זה רק לקישוט

Sheet מתכונים
A1: עלות לכל מתכון (12 יחידות; סמבוסקים: 20). הכמויות בכחול ניתנות לשינוי, והעלויות מתעדכנות.
A3: מתכון | B3: מוצר | C3: כמות | D3: יחידה | E3: מחיר אריזה | F3: כמות באריזה | G3: עלות בפועל
A4: 1. מאפינס בטטה ותירס (גם לתינוקת) | B4: יוגורט 3% גביע 200 גרם | C4: 240 | D4: =INDEX(מחירים!$B$5:$B$20,MATCH(B4,מחירים!$A$5:$A$20,0)) -> גרם | E4: =INDEX(מחירים!$D$5:$D$20,MATCH(B4,מחירים!$A$5:$A$20,0)) -> 3.9 | F4: =INDEX(מחירים!$C$5:$C$20,MATCH(B4,מחירים!$A$5:$A$20,0)) -> 200 | G4: =C4/F4*E4 -> 4.68
A5: 1. מאפינס בטטה ותירס (גם לתינוקת) | B5: ביצים L, 12 יח' | C5: 2 | D5: =INDEX(מחירים!$B$5:$B$20,MATCH(B5,מחירים!$A$5:$A$20,0)) -> יחידה | E5: =INDEX(מחירים!$D$5:$D$20,MATCH(B5,מחירים!$A$5:$A$20,0)) -> 14 | F5: =INDEX(מחירים!$C$5:$C$20,MATCH(B5,מחירים!$A$5:$A$20,0)) -> 12 | G5: =C5/F5*E5 -> 2.3333333
A6: 1. מאפינס בטטה ותירס (גם לתינוקת) | B6: שמן קנולה רמי לוי 1 ליטר | C6: 60 | D6: =INDEX(מחירים!$B$5:$B$20,MATCH(B6,מחירים!$A$5:$A$20,0)) -> מ"ל | E6: =INDEX(מחירים!$D$5:$D$20,MATCH(B6,מחירים!$A$5:$A$20,0)) -> 8.9 | F6: =INDEX(מחירים!$C$5:$C$20,MATCH(B6,מחירים!$A$5:$A$20,0)) -> 1000 | G6: =C6/F6*E6 -> 0.534
A7: 1. מאפינס בטטה ותירס (גם לתינוקת) | B7: קמח כוסמין מלא 100% נפלאות 1 ק"ג | C7: 180 | D7: =INDEX(מחירים!$B$5:$B$20,MATCH(B7,מחירים!$A$5:$A$20,0)) -> גרם | E7: =INDEX(מחירים!$D$5:$D$20,MATCH(B7,מחירים!$A$5:$A$20,0)) -> 14.7 | F7: =INDEX(מחירים!$C$5:$C$20,MATCH(B7,מחירים!$A$5:$A$20,0)) -> 1000 | G7: =C7/F7*E7 -> 2.646
A8: 1. מאפינס בטטה ותירס (גם לתינוקת) | B8: אבקת אפייה 150 גרם | C8: 8 | D8: =INDEX(מחירים!$B$5:$B$20,MATCH(B8,מחירים!$A$5:$A$20,0)) -> גרם | E8: =INDEX(מחירים!$D$5:$D$20,MATCH(B8,מחירים!$A$5:$A$20,0)) -> 4.9 | F8: =INDEX(מחירים!$C$5:$C$20,MATCH(B8,מחירים!$A$5:$A$20,0)) -> 150 | G8: =C8/F8*E8 -> 0.26133333
A9: 1. מאפינס בטטה ותירס (גם לתינוקת) | B9: בטטה (לק"ג) | C9: 300 | D9: =INDEX(מחירים!$B$5:$B$20,MATCH(B9,מחירים!$A$5:$A$20,0)) -> גרם | E9: =INDEX(מחירים!$D$5:$D$20,MATCH(B9,מחירים!$A$5:$A$20,0)) -> 7.9 | F9: =INDEX(מחירים!$C$5:$C$20,MATCH(B9,מחירים!$A$5:$A$20,0)) -> 1000 | G9: =C9/F9*E9 -> 2.37
A10: 1. מאפינס בטטה ותירס (גם לתינוקת) | B10: תירס מתוק שימורים רמי לוי 335 גרם | C10: 75 | D10: =INDEX(מחירים!$B$5:$B$20,MATCH(B10,מחירים!$A$5:$A$20,0)) -> גרם (מסונן) | E10: =INDEX(מחירים!$D$5:$D$20,MATCH(B10,מחירים!$A$5:$A$20,0)) -> 8.4 | F10: =INDEX(מחירים!$C$5:$C$20,MATCH(B10,מחירים!$A$5:$A$20,0)) -> 230 | G10: =C10/F10*E10 -> 2.7391304
A11: 1. מאפינס בטטה ותירס (גם לתינוקת) | B11: קוטג' 5% 250 גרם | C11: 80 | D11: =INDEX(מחירים!$B$5:$B$20,MATCH(B11,מחירים!$A$5:$A$20,0)) -> גרם | E11: =INDEX(מחירים!$D$5:$D$20,MATCH(B11,מחירים!$A$5:$A$20,0)) -> 6.6 | F11: =INDEX(מחירים!$C$5:$C$20,MATCH(B11,מחירים!$A$5:$A$20,0)) -> 250 | G11: =C11/F11*E11 -> 2.112
B12: סה"כ למתכון | G12: =SUM(G4:G11) -> 17.675797
A14: 2. מאפינס ברוקולי וקישוא (גם לתינוקת) | B14: יוגורט 3% גביע 200 גרם | C14: 240 | D14: =INDEX(מחירים!$B$5:$B$20,MATCH(B14,מחירים!$A$5:$A$20,0)) -> גרם | E14: =INDEX(מחירים!$D$5:$D$20,MATCH(B14,מחירים!$A$5:$A$20,0)) -> 3.9 | F14: =INDEX(מחירים!$C$5:$C$20,MATCH(B14,מחירים!$A$5:$A$20,0)) -> 200 | G14: =C14/F14*E14 -> 4.68
A15: 2. מאפינס ברוקולי וקישוא (גם לתינוקת) | B15: ביצים L, 12 יח' | C15: 2 | D15: =INDEX(מחירים!$B$5:$B$20,MATCH(B15,מחירים!$A$5:$A$20,0)) -> יחידה | E15: =INDEX(מחירים!$D$5:$D$20,MATCH(B15,מחירים!$A$5:$A$20,0)) -> 14 | F15: =INDEX(מחירים!$C$5:$C$20,MATCH(B15,מחירים!$A$5:$A$20,0)) -> 12 | G15: =C15/F15*E15 -> 2.3333333
A16: 2. מאפינס ברוקולי וקישוא (גם לתינוקת) | B16: שמן קנולה רמי לוי 1 ליטר | C16: 60 | D16: =INDEX(מחירים!$B$5:$B$20,MATCH(B16,מחירים!$A$5:$A$20,0)) -> מ"ל | E16: =INDEX(מחירים!$D$5:$D$20,MATCH(B16,מחירים!$A$5:$A$20,0)) -> 8.9 | F16: =INDEX(מחירים!$C$5:$C$20,MATCH(B16,מחירים!$A$5:$A$20,0)) -> 1000 | G16: =C16/F16*E16 -> 0.534
A17: 2. מאפינס ברוקולי וקישוא (גם לתינוקת) | B17: קמח כוסמין מלא 100% נפלאות 1 ק"ג | C17: 180 | D17: =INDEX(מחירים!$B$5:$B$20,MATCH(B17,מחירים!$A$5:$A$20,0)) -> גרם | E17: =INDEX(מחירים!$D$5:$D$20,MATCH(B17,מחירים!$A$5:$A$20,0)) -> 14.7 | F17: =INDEX(מחירים!$C$5:$C$20,MATCH(B17,מחירים!$A$5:$A$20,0)) -> 1000 | G17: =C17/F17*E17 -> 2.646
A18: 2. מאפינס ברוקולי וקישוא (גם לתינוקת) | B18: אבקת אפייה 150 גרם | C18: 8 | D18: =INDEX(מחירים!$B$5:$B$20,MATCH(B18,מחירים!$A$5:$A$20,0)) -> גרם | E18: =INDEX(מחירים!$D$5:$D$20,MATCH(B18,מחירים!$A$5:$A$20,0)) -> 4.9 | F18: =INDEX(מחירים!$C$5:$C$20,MATCH(B18,מחירים!$A$5:$A$20,0)) -> 150 | G18: =C18/F18*E18 -> 0.26133333
A19: 2. מאפינס ברוקולי וקישוא (גם לתינוקת) | B19: ברוקולי קפוא רמי לוי 800 גרם | C19: 150 | D19: =INDEX(מחירים!$B$5:$B$20,MATCH(B19,מחירים!$A$5:$A$20,0)) -> גרם | E19: =INDEX(מחירים!$D$5:$D$20,MATCH(B19,מחירים!$A$5:$A$20,0)) -> 13.9 | F19: =INDEX(מחירים!$C$5:$C$20,MATCH(B19,מחירים!$A$5:$A$20,0)) -> 800 | G19: =C19/F19*E19 -> 2.60625
A20: 2. מאפינס ברוקולי וקישוא (גם לתינוקת) | B20: קישוא (לק"ג) | C20: 200 | D20: =INDEX(מחירים!$B$5:$B$20,MATCH(B20,מחירים!$A$5:$A$20,0)) -> גרם | E20: =INDEX(מחירים!$D$5:$D$20,MATCH(B20,מחירים!$A$5:$A$20,0)) -> 8.9 | F20: =INDEX(מחירים!$C$5:$C$20,MATCH(B20,מחירים!$A$5:$A$20,0)) -> 1000 | G20: =C20/F20*E20 -> 1.78
A21: 2. מאפינס ברוקולי וקישוא (גם לתינוקת) | B21: קוטג' 5% 250 גרם | C21: 100 | D21: =INDEX(מחירים!$B$5:$B$20,MATCH(B21,מחירים!$A$5:$A$20,0)) -> גרם | E21: =INDEX(מחירים!$D$5:$D$20,MATCH(B21,מחירים!$A$5:$A$20,0)) -> 6.6 | F21: =INDEX(מחירים!$C$5:$C$20,MATCH(B21,מחירים!$A$5:$A$20,0)) -> 250 | G21: =C21/F21*E21 -> 2.64
B22: סה"כ למתכון | G22: =SUM(G14:G21) -> 17.480917
A24: 3. פיצה מגש לריבועים | B24: יוגורט 3% גביע 200 גרם | C24: 250 | D24: =INDEX(מחירים!$B$5:$B$20,MATCH(B24,מחירים!$A$5:$A$20,0)) -> גרם | E24: =INDEX(מחירים!$D$5:$D$20,MATCH(B24,מחירים!$A$5:$A$20,0)) -> 3.9 | F24: =INDEX(מחירים!$C$5:$C$20,MATCH(B24,מחירים!$A$5:$A$20,0)) -> 200 | G24: =C24/F24*E24 -> 4.875
A25: 3. פיצה מגש לריבועים | B25: שמן קנולה רמי לוי 1 ליטר | C25: 30 | D25: =INDEX(מחירים!$B$5:$B$20,MATCH(B25,מחירים!$A$5:$A$20,0)) -> מ"ל | E25: =INDEX(מחירים!$D$5:$D$20,MATCH(B25,מחירים!$A$5:$A$20,0)) -> 8.9 | F25: =INDEX(מחירים!$C$5:$C$20,MATCH(B25,מחירים!$A$5:$A$20,0)) -> 1000 | G25: =C25/F25*E25 -> 0.267
A26: 3. פיצה מגש לריבועים | B26: קמח כוסמין מלא 100% נפלאות 1 ק"ג | C26: 300 | D26: =INDEX(מחירים!$B$5:$B$20,MATCH(B26,מחירים!$A$5:$A$20,0)) -> גרם | E26: =INDEX(מחירים!$D$5:$D$20,MATCH(B26,מחירים!$A$5:$A$20,0)) -> 14.7 | F26: =INDEX(מחירים!$C$5:$C$20,MATCH(B26,מחירים!$A$5:$A$20,0)) -> 1000 | G26: =C26/F26*E26 -> 4.41
A27: 3. פיצה מגש לריבועים | B27: אבקת אפייה 150 גרם | C27: 10 | D27: =INDEX(מחירים!$B$5:$B$20,MATCH(B27,מחירים!$A$5:$A$20,0)) -> גרם | E27: =INDEX(מחירים!$D$5:$D$20,MATCH(B27,מחירים!$A$5:$A$20,0)) -> 4.9 | F27: =INDEX(מחירים!$C$5:$C$20,MATCH(B27,מחירים!$A$5:$A$20,0)) -> 150 | G27: =C27/F27*E27 -> 0.32666667
A28: 3. פיצה מגש לריבועים | B28: רסק עגבניות 100 גרם | C28: 100 | D28: =INDEX(מחירים!$B$5:$B$20,MATCH(B28,מחירים!$A$5:$A$20,0)) -> גרם | E28: =INDEX(מחירים!$D$5:$D$20,MATCH(B28,מחירים!$A$5:$A$20,0)) -> 1.9 | F28: =INDEX(מחירים!$C$5:$C$20,MATCH(B28,מחירים!$A$5:$A$20,0)) -> 100 | G28: =C28/F28*E28 -> 1.9
A29: 3. פיצה מגש לריבועים | B29: מוצרלה מגורדת 200 גרם | C29: 100 | D29: =INDEX(מחירים!$B$5:$B$20,MATCH(B29,מחירים!$A$5:$A$20,0)) -> גרם | E29: =INDEX(מחירים!$D$5:$D$20,MATCH(B29,מחירים!$A$5:$A$20,0)) -> 19.7 | F29: =INDEX(מחירים!$C$5:$C$20,MATCH(B29,מחירים!$A$5:$A$20,0)) -> 200 | G29: =C29/F29*E29 -> 9.85
A30: 3. פיצה מגש לריבועים | B30: תירס מתוק שימורים רמי לוי 335 גרם | C30: 75 | D30: =INDEX(מחירים!$B$5:$B$20,MATCH(B30,מחירים!$A$5:$A$20,0)) -> גרם (מסונן) | E30: =INDEX(מחירים!$D$5:$D$20,MATCH(B30,מחירים!$A$5:$A$20,0)) -> 8.4 | F30: =INDEX(מחירים!$C$5:$C$20,MATCH(B30,מחירים!$A$5:$A$20,0)) -> 230 | G30: =C30/F30*E30 -> 2.7391304
A31: 3. פיצה מגש לריבועים | B31: קישוא (לק"ג) | C31: 150 | D31: =INDEX(מחירים!$B$5:$B$20,MATCH(B31,מחירים!$A$5:$A$20,0)) -> גרם | E31: =INDEX(מחירים!$D$5:$D$20,MATCH(B31,מחירים!$A$5:$A$20,0)) -> 8.9 | F31: =INDEX(מחירים!$C$5:$C$20,MATCH(B31,מחירים!$A$5:$A$20,0)) -> 1000 | G31: =C31/F31*E31 -> 1.335
A32: 3. פיצה מגש לריבועים | B32: ברוקולי קפוא רמי לוי 800 גרם | C32: 100 | D32: =INDEX(מחירים!$B$5:$B$20,MATCH(B32,מחירים!$A$5:$A$20,0)) -> גרם | E32: =INDEX(מחירים!$D$5:$D$20,MATCH(B32,מחירים!$A$5:$A$20,0)) -> 13.9 | F32: =INDEX(מחירים!$C$5:$C$20,MATCH(B32,מחירים!$A$5:$A$20,0)) -> 800 | G32: =C32/F32*E32 -> 1.7375
B33: סה"כ למתכון | G33: =SUM(G24:G32) -> 27.440297
A35: 4. שבלולי ברוקולי וקוטג' | B35: יוגורט 3% גביע 200 גרם | C35: 250 | D35: =INDEX(מחירים!$B$5:$B$20,MATCH(B35,מחירים!$A$5:$A$20,0)) -> גרם | E35: =INDEX(מחירים!$D$5:$D$20,MATCH(B35,מחירים!$A$5:$A$20,0)) -> 3.9 | F35: =INDEX(מחירים!$C$5:$C$20,MATCH(B35,מחירים!$A$5:$A$20,0)) -> 200 | G35: =C35/F35*E35 -> 4.875
A36: 4. שבלולי ברוקולי וקוטג' | B36: שמן קנולה רמי לוי 1 ליטר | C36: 30 | D36: =INDEX(מחירים!$B$5:$B$20,MATCH(B36,מחירים!$A$5:$A$20,0)) -> מ"ל | E36: =INDEX(מחירים!$D$5:$D$20,MATCH(B36,מחירים!$A$5:$A$20,0)) -> 8.9 | F36: =INDEX(מחירים!$C$5:$C$20,MATCH(B36,מחירים!$A$5:$A$20,0)) -> 1000 | G36: =C36/F36*E36 -> 0.267
A37: 4. שבלולי ברוקולי וקוטג' | B37: קמח כוסמין מלא 100% נפלאות 1 ק"ג | C37: 300 | D37: =INDEX(מחירים!$B$5:$B$20,MATCH(B37,מחירים!$A$5:$A$20,0)) -> גרם | E37: =INDEX(מחירים!$D$5:$D$20,MATCH(B37,מחירים!$A$5:$A$20,0)) -> 14.7 | F37: =INDEX(מחירים!$C$5:$C$20,MATCH(B37,מחירים!$A$5:$A$20,0)) -> 1000 | G37: =C37/F37*E37 -> 4.41
A38: 4. שבלולי ברוקולי וקוטג' | B38: אבקת אפייה 150 גרם | C38: 10 | D38: =INDEX(מחירים!$B$5:$B$20,MATCH(B38,מחירים!$A$5:$A$20,0)) -> גרם | E38: =INDEX(מחירים!$D$5:$D$20,MATCH(B38,מחירים!$A$5:$A$20,0)) -> 4.9 | F38: =INDEX(מחירים!$C$5:$C$20,MATCH(B38,מחירים!$A$5:$A$20,0)) -> 150 | G38: =C38/F38*E38 -> 0.32666667
A39: 4. שבלולי ברוקולי וקוטג' | B39: ברוקולי קפוא רמי לוי 800 גרם | C39: 300 | D39: =INDEX(מחירים!$B$5:$B$20,MATCH(B39,מחירים!$A$5:$A$20,0)) -> גרם | E39: =INDEX(מחירים!$D$5:$D$20,MATCH(B39,מחירים!$A$5:$A$20,0)) -> 13.9 | F39: =INDEX(מחירים!$C$5:$C$20,MATCH(B39,מחירים!$A$5:$A$20,0)) -> 800 | G39: =C39/F39*E39 -> 5.2125
A40: 4. שבלולי ברוקולי וקוטג' | B40: קוטג' 5% 250 גרם | C40: 220 | D40: =INDEX(מחירים!$B$5:$B$20,MATCH(B40,מחירים!$A$5:$A$20,0)) -> גרם | E40: =INDEX(מחירים!$D$5:$D$20,MATCH(B40,מחירים!$A$5:$A$20,0)) -> 6.6 | F40: =INDEX(מחירים!$C$5:$C$20,MATCH(B40,מחירים!$A$5:$A$20,0)) -> 250 | G40: =C40/F40*E40 -> 5.808
A41: 4. שבלולי ברוקולי וקוטג' | B41: ביצים L, 12 יח' | C41: 1 | D41: =INDEX(מחירים!$B$5:$B$20,MATCH(B41,מחירים!$A$5:$A$20,0)) -> יחידה | E41: =INDEX(מחירים!$D$5:$D$20,MATCH(B41,מחירים!$A$5:$A$20,0)) -> 14 | F41: =INDEX(מחירים!$C$5:$C$20,MATCH(B41,מחירים!$A$5:$A$20,0)) -> 12 | G41: =C41/F41*E41 -> 1.1666667
A42: 4. שבלולי ברוקולי וקוטג' | B42: מוצרלה מגורדת 200 גרם | C42: 50 | D42: =INDEX(מחירים!$B$5:$B$20,MATCH(B42,מחירים!$A$5:$A$20,0)) -> גרם | E42: =INDEX(מחירים!$D$5:$D$20,MATCH(B42,מחירים!$A$5:$A$20,0)) -> 19.7 | F42: =INDEX(מחירים!$C$5:$C$20,MATCH(B42,מחירים!$A$5:$A$20,0)) -> 200 | G42: =C42/F42*E42 -> 4.925
B43: סה"כ למתכון | G43: =SUM(G35:G42) -> 26.990833
A45: 5. סמבוסקי פיצה וטונה (מהסרטון) | B45: קמח לבן רמי לוי 1 ק"ג | C45: 140 | D45: =INDEX(מחירים!$B$5:$B$20,MATCH(B45,מחירים!$A$5:$A$20,0)) -> גרם | E45: =INDEX(מחירים!$D$5:$D$20,MATCH(B45,מחירים!$A$5:$A$20,0)) -> 3.8 | F45: =INDEX(מחירים!$C$5:$C$20,MATCH(B45,מחירים!$A$5:$A$20,0)) -> 1000 | G45: =C45/F45*E45 -> 0.532
...
